Workbook

Sheet Tablero
B1: TABLERO DEL PARQUEADERO
B4: AÑO | D4: Ingresos totales | H4: Vehículos atendidos | L4: Cobro promedio | P4: Ventas de la tienda | T4: Margen de la tienda | X4: Tiempo promedio (min) | AB4: Visitas que vuelven | AF4: Crecimiento vs mes anterior | AJ4: Cumplimiento de la meta
B5: 2026 | D5: $ | H5: 🚗 | L5: ⏱ | P5: 🛒 | T5: % | X5: 🕑 | AB5: ↻ | AF5: ▲ | AJ5: ◎
D6: =Cálculos!$E$3+Cálculos!$E$5 -> 10833687 | H6: =Cálculos!$E$4 -> 1150 | L6: =IF(Cálculos!$E$4=0,0,Cálculos!$E$3/Cálculos!$E$4) -> 6860.5974 | P6: =Cálculos!$E$5 -> 2944000 | T6: =IF(Cálculos!$E$5=0,0,(Cálculos!$E$5-Cálculos!$E$6)/Cálculos!$E$5) -> 0.3608356 | X6: =IF(Cálculos!$E$4=0,0,Cálculos!$E$8/Cálculos!$E$4) -> 225.44957 | AB6: =IF(Cálculos!$E$4=0,0,1-Cálculos!$E$9/Cálculos!$E$4) -> 0.8626087 | AF6: =IF(Cálculos!$E$11=0,"—",(Cálculos!$E$3+Cálculos!$E$5)/Cálculos!$E$11-1) -> — | AJ6: =IF(Tablero!$B$14=0,0,(Cálculos!$E$3+Cálculos!$E$5)/(Tablero!$B$14*Cálculos!$B$8)) -> 0.24566184
B7: MES
B8: Todos
B10: TRABAJADOR
B11: Todos
B13: META DE VENTAS POR DÍA
B14: 150000
B16: Las celdas blancas tienen una lista: toque la flechita para cambiar el filtro.

Sheet Cómo usarlo
B2: CÓMO USAR ESTE TABLERO
B4: 1. En la app entre a Tablero, elija el año y toque "Datos para el Excel". Se descarga un archivo con las hojas Cobros, Ventas, Gastos y Listas.
B5: 2. Abra ese archivo, copie las columnas de cada hoja (desde la fila 2) y péguelas en la hoja del mismo nombre de este Excel, desde la celda A2.
B6: Antes de pegar, borre los datos de ejemplo (texto azul) de las columnas A a I (Cobros), A a H (Ventas) y A a C (Gastos).
B7: 3. Vaya a la hoja Tablero y use los filtros de la izquierda: Año, Mes y Trabajador. Todo se recalcula solo.
B8: 4. Copie también los nombres de la hoja Listas del archivo descargado: trabajadores en Listas!D3 y categorías en Listas!F2 de este Excel.
B9: 5. La META DE VENTAS POR DÍA (celda amarilla) la pone usted.
B11: Qué celdas se tocan: solo los filtros (celdas blancas con lista), la meta (amarilla) y los datos pegados (texto azul).
B12: Todo lo demás son fórmulas: no las borre.
B13: Las hojas tienen espacio para 5.000 cobros y 5.000 ventas por archivo (más o menos un año). Para más, haga un archivo por año.
B15: Los datos que trae este archivo son DE EJEMPLO (inventados) para que vea cómo se ve con datos. Reemplácelos por los suyos.
B16: Las gráficas por mes muestran el año elegido completo; los indicadores de arriba y las gráficas de categorías respetan también el filtro de mes.

Sheet Cobros
A1: Fecha y hora de salida | B1: Hora de entrada | C1: Placa | D1: Vehículo | E1: Minutos | F1: Total ($) | G1: Pago | H1: Atendió | I1: Modalidad | J1: Año | K1: Mes | L1: Hora llegada | M1: Primera vez en el año | O1: Columnas A a I: pegue aquí los cobros que descarga la app (Tablero › "Datos para el Excel"). Las columnas J a M se calculan solas.
A2: 45658.38 | B2: 07:35 | C2: RCF274 | D2: Moto | E2: 92 | F2: 0 | G2: Fiado | H2: Luisa Trujillo | I2: Mensualidad | J2: =IF(A2="","",YEAR(A2)) -> 2025 | K2: =IF(A2="","",MONTH(A2)) -> 1 | L2: =IF(B2="","",VALUE(LEFT(B2,2))) -> 7 | M2: =IF(A2="","",IF(COUNTIFS($C$2:$C$5001,C2,$J$2:$J$5001,J2,$A$2:$A$5001,"<"&A2)=0,1,0)) -> 1
A3: 45658.483 | B3: 09:16 | C3: LKA249 | D3: Moto | E3: 140 | F3: 2500 | G3: Efectivo | H3: Carlos Perdomo | I3: Por tiempo | J3: =IF(A3="","",YEAR(A3)) -> 2025 | K3: =IF(A3="","",MONTH(A3)) -> 1 | L3: =IF(B3="","",VALUE(LEFT(B3,2))) -> 9 | M3: =IF(A3="","",IF(COUNTIFS($C$2:$C$5001,C3,$J$2:$J$5001,J3,$A$2:$A$5001,"<"&A3)=0,1,0)) -> 1
A4: 45658.885 | B4: 17:24 | C4: YBV699 | D4: Moto | E4: 231 | F4: 4000 | G4: Efectivo | H4: Luisa Trujillo | I4: Por tiempo | J4: =IF(A4="","",YEAR(A4)) -> 2025 | K4: =IF(A4="","",MONTH(A4)) -> 1 | L4: =IF(B4="","",VALUE(LEFT(B4,2))) -> 17 | M4: =IF(A4="","",IF(COUNTIFS($C$2:$C$5001,C4,$J$2:$J$5001,J4,$A$2:$A$5001,"<"&A4)=0,1,0)) -> 1
A5: 45659.338 | B5: 07:34 | C5: JMD660 | D5: Carro | E5: 32 | F5: 2000 | G5: Efectivo | H5: Luisa Trujillo | I5: Por tiempo | J5: =IF(A5="","",YEAR(A5)) -> 2025 | K5: =IF(A5="","",MONTH(A5)) -> 1 | L5: =IF(B5="","",VALUE(LEFT(B5,2))) -> 7 | M5: =IF(A5="","",IF(COUNTIFS($C$2:$C$5001,C5,$J$2:$J$5001,J5,$A$2:$A$5001,"<"&A5)=0,1,0)) -> 1
A6: 45659.415 | B6: 06:36 | C6: FMW126 | D6: Carro | E6: 201 | F6: 7000 | G6: Transferencia | H6: Luisa Trujillo | I6: Por tiempo | J6: =IF(A6="","",YEAR(A6)) -> 2025 | K6: =IF(A6="","",MONTH(A6)) -> 1 | L6: =IF(B6="","",VALUE(LEFT(B6,2))) -> 6 | M6: =IF(A6="","",IF(COUNTIFS($C$2:$C$5001,C6,$J$2:$J$5001,J6,$A$2:$A$5001,"<"&A6)=0,1,0)) -> 1
A7: 45659.628 | B7: 08:21 | C7: YDH745 | D7: Tractomula | E7: 403 | F7: 0 | G7: Efectivo | H7: Luisa Trujillo | I7: Mensualidad | J7: =IF(A7="","",YEAR(A7)) -> 2025 | K7: =IF(A7="","",MONTH(A7)) -> 1 | L7: =IF(B7="","",VALUE(LEFT(B7,2))) -> 8 | M7: =IF(A7="","",IF(COUNTIFS($C$2:$C$5001,C7,$J$2:$J$5001,J7,$A$2:$A$5001,"<"&A7)=0,1,0)) -> 1
A8: 45659.643 | B8: 10:01 | C8: NWB204 | D8: Carro | E8: 325 | F8: 11000 | G8: Efectivo | H8: Luisa Trujillo | I8: Por tiempo | J8: =IF(A8="","",YEAR(A8)) -> 2025 | K8: =IF(A8="","",MONTH(A8)) -> 1 | L8: =IF(B8="","",VALUE(LEFT(B8,2))) -> 10 | M8: =IF(A8="","",IF(COUNTIFS($C$2:$C$5001,C8,$J$2:$J$5001,J8,$A$2:$A$5001,"<"&A8)=0,1,0)) -> 1
A9: 45659.759 | B9: 16:33 | C9: XVL448 | D9: Carro | E9: 100 | F9: 4000 | G9: Efectivo | H9: Luisa Trujillo | I9: Por tiempo | J9: =IF(A9="","",YEAR(A9)) -> 2025 | K9: =IF(A9="","",MONTH(A9)) -> 1 | L9: =IF(B9="","",VALUE(LEFT(B9,2))) -> 16 | M9: =IF(A9="","",IF(COUNTIFS($C$2:$C$5001,C9,$J$2:$J$5001,J9,$A$2:$A$5001,"<"&A9)=0,1,0)) -> 1
A10: 45659.787 | B10: 16:01 | C10: RHG630 | D10: Carro | E10: 173 | F10: 6000 | G10: Dividido | H10: Andrea Bolívar | I10: Por tiempo | J10: =IF(A10="","",YEAR(A10)) -> 2025 | K10: =IF(A10="","",MONTH(A10)) -> 1 | L10: =IF(B10="","",VALUE(LEFT(B10,2))) -> 16 | M10: =IF(A10="","",IF(COUNTIFS($C$2:$C$5001,C10,$J$2:$J$5001,J10,$A$2:$A$5001,"<"&A10)=0,1,0)) -> 1
A11: 45660.583 | B11: 07:00 | C11: KEC280 | D11: Carro | E11: 420 | F11: 14000 | G11: Monedero | H11: Luisa Trujillo | I11: Por tiempo | J11: =IF(A11="","",YEAR(A11)) -> 2025 | K11: =IF(A11="","",MONTH(A11)) -> 1 | L11: =IF(B11="","",VALUE(LEFT(B11,2))) -> 7 | M11: =IF(A11="","",IF(COUNTIFS($C$2:$C$5001,C11,$J$2:$J$5001,J11,$A$2:$A$5001,"<"&A11)=0,1,0)) -> 1
A12: 45660.629 | B12: 10:32 | C12: VKC247 | D12: Moto | E12: 274 | F12: 5000 | G12: Efectivo | H12: Luisa Trujillo | I12: Por tiempo | J12: =IF(A12="","",YEAR(A12)) -> 2025 | K12: =IF(A12="","",MONTH(A12)) -> 1 | L12: =IF(B12="","",VALUE(LEFT(B12,2))) -> 10 | M12: =IF(A12="","",IF(COUNTIFS($C$2:$C$5001,C12,$J$2:$J$5001,J12,$A$2:$A$5001,"<"&A12)=0,1,0)) -> 1
A13: 45661.385 | B13: 07:40 | C13: MEH507 | D13: Bus | E13: 94 | F13: 6000 | G13: Monedero | H13: Andrea Bolívar | I13: Por tiempo | J13: =IF(A13="","",YEAR(A13)) -> 2025 | K13: =IF(A13="","",MONTH(A13)) -> 1 | L13: =IF(B13="","",VALUE(LEFT(B13,2))) -> 7 | M13: =IF(A13="","",IF(COUNTIFS($C$2:$C$5001,C13,$J$2:$J$5001,J13,$A$2:$A$5001,"<"&A13)=0,1,0)) -> 1
... A2461: 46322.958 | B2461: 20:18 | C2461: RDS749 | D2461: Carro | E2461: 162 | F2461: 5100 | G2461: Transferencia | H2461: Andrea Bolívar | I2461: Convenio | J2461: =IF(A2461="","",YEAR(A2461)) -> 2026 | K2461: =IF(A2461="","",MONTH(A2461)) -> 10 | L2461: =IF(B2461="","",VALUE(LEFT(B2461,2))) -> 20 | M2461: =IF(A2461="","",IF(COUNTIFS($C$2:$C$5001,C2461,$J$2:$J$5001,J2461,$A$2:$A$5001,"<"&A2461)=0,1,0)) -> 0
J2462: =IF(A2462="","",YEAR(A2462)) | K2462: =IF(A2462="","",MONTH(A2462)) | L2462: =IF(B2462="","",VALUE(LEFT(B2462,2))) | M2462: =IF(A2462="","",IF(COUNTIFS($C$2:$C$5001,C2462,$J$2:$J$5001,J2462,$A$2:$A$5001,"<"&A2462)=0,1,0))
J2463: =IF(A2463="","",YEAR(A2463)) | K2463: =IF(A2463="","",MONTH(A2463)) | L2463: =IF(B2463="","",VALUE(LEFT(B2463,2))) | M2463: =IF(A2463="","",IF(COUNTIFS($C$2:$C$5001,C2463,$J$2:$J$5001,J2463,$A$2:$A$5001,"<"&A2463)=0,1,0))
J2464: =IF(A2464="","",YEAR(A2464)) | K2464: =IF(A2464="","",MONTH(A2464)) | L2464: =IF(B2464="","",VALUE(LEFT(B2464,2))) | M2464: =IF(A2464="","",IF(COUNTIFS($C$2:$C$5001,C2464,$J$2:$J$5001,J2464,$A$2:$A$5001,"<"&A2464)=0,1,0))
J2465: =IF(A2465="","",YEAR(A2465)) | K2465: =IF(A2465="","",MONTH(A2465)) | L2465: =IF(B2465="","",VALUE(LEFT(B2465,2))) | M2465: =IF(A2465="","",IF(COUNTIFS($C$2:$C$5001,C2465,$J$2:$J$5001,J2465,$A$2:$A$5001,"<"&A2465)=0,1,0))
J2466: =IF(A2466="","",YEAR(A2466)) | K2466: =IF(A2466="","",MONTH(A2466)) | L2466: =IF(B2466="","",VALUE(LEFT(B2466,2))) | M2466: =IF(A2466="","",IF(COUNTIFS($C$2:$C$5001,C2466,$J$2:$J$5001,J2466,$A$2:$A$5001,"<"&A2466)=0,1,0))
J2467: =IF(A2467="","",YEAR(A2467)) | K2467: =IF(A2467="","",MONTH(A2467)) | L2467: =IF(B2467="","",VALUE(LEFT(B2467,2))) | M2467: =IF(A2467="","",IF(COUNTIFS($C$2:$C$5001,C2467,$J$2:$J$5001,J2467,$A$2:$A$5001,"<"&A2467)=0,1,0))
J2468: =IF(A2468="","",YEAR(A2468)) | K2468: =IF(A2468="","",MONTH(A2468)) | L2468: =IF(B2468="","",VALUE(LEFT(B2468,2))) | M2468: =IF(A2468="","",IF(COUNTIFS($C$2:$C$5001,C2468,$J$2:$J$5001,J2468,$A$2:$A$5001,"<"&A2468)=0,1,0))
J2469: =IF(A2469="","",YEAR(A2469)) | K2469: =IF(A2469="","",MONTH(A2469)) | L2469: =IF(B2469="","",VALUE(LEFT(B2469,2))) | M2469: =IF(A2469="","",IF(COUNTIFS($C$2:$C$5001,C2469,$J$2:$J$5001,J2469,$A$2:$A$5001,"<"&A2469)=0,1,0))
J2470: =IF(A2470="","",YEAR(A2470)) | K2470: =IF(A2470="","",MONTH(A2470)) | L2470: =IF(B2470="","",VALUE(LEFT(B2470,2))) | M2470: =IF(A2470="","",IF(COUNTIFS($C$2:$C$5001,C2470,$J$2:$J$5001,J2470,$A$2:$A$5001,"<"&A2470)=0,1,0))
J2471: =IF(A2471="","",YEAR(A2471)) | K2471: =IF(A2471="","",MONTH(A2471)) | L2471: =IF(B2471="","",VALUE(LEFT(B2471,2))) | M2471: =IF(A2471="","",IF(COUNTIFS($C$2:$C$5001,C2471,$J$2:$J$5001,J2471,$A$2:$A$5001,"<"&A2471)=0,1,0))
J2472: =IF(A2472="","",YEAR(A2472)) | K2472: =IF(A2472="","",MONTH(A2472)) | L2472: =IF(B2472="","",VALUE(LEFT(B2472,2))) | M2472: =IF(A2472="","",IF(COUNTIFS($C$2:$C$5001,C2472,$J$2:$J$5001,J2472,$A$2:$A$5001,"<"&A2472)=0,1,0))
J2473: =IF(A2473="","",YEAR(A2473)) | K2473: =IF(A2473="","",MONTH(A2473)) | L2473: =IF(B2473="","",VALUE(LEFT(B2473,2))) | M2473: =IF(A2473="","",IF(COUNTIFS($C$2:$C$5001,C2473,$J$2:$J$5001,J2473,$A$2:$A$5001,"<"&A2473)=0,1,0))
... J5001: =IF(A5001="","",YEAR(A5001)) | K5001: =IF(A5001="","",MONTH(A5001)) | L5001: =IF(B5001="","",VALUE(LEFT(B5001,2))) | M5001: =IF(A5001="","",IF(COUNTIFS($C$2:$C$5001,C5001,$J$2:$J$5001,J5001,$A$2:$A$5001,"<"&A5001)=0,1,0))

Sheet Ventas
A1: Fecha y hora | B1: Producto | C1: Categoría | D1: Cantidad | E1: Precio ($) | F1: Costo unitario ($) | G1: Pago | H1: Atendió | I1: Total ($) | J1: Costo total ($) | K1: Año | L1: Mes | N1: Columnas A a H: pegue aquí las ventas de la app. Las columnas I a L se calculan solas.
A2: 45660.582 | B2: Coca-Cola 400 ml | C2: Gaseosas | D2: 2 | E2: 3000 | F2: 2000 | G2: Efectivo | H2: Luisa Trujillo | I2: =IF(A2="","",D2*E2) -> 6000 | J2: =IF(A2="","",D2*F2) -> 4000 | K2: =IF(A2="","",YEAR(A2)) -> 2025 | L2: =IF(A2="","",MONTH(A2)) -> 1
A3: 45662.888 | B3: Club Colombia | C3: Cerveza | D3: 2 | E3: 4000 | F3: 2600 | G3: Efectivo | H3: Luisa Trujillo | I3: =IF(A3="","",D3*E3) -> 8000 | J3: =IF(A3="","",D3*F3) -> 5200 | K3: =IF(A3="","",YEAR(A3)) -> 2025 | L3: =IF(A3="","",MONTH(A3)) -> 1
A4: 45663.581 | B4: Gatorade 500 ml | C4: Bebidas | D4: 1 | E4: 4500 | F4: 3000 | G4: Transferencia | H4: Andrea Bolívar | I4: =IF(A4="","",D4*E4) -> 4500 | J4: =IF(A4="","",D4*F4) -> 3000 | K4: =IF(A4="","",YEAR(A4)) -> 2025 | L4: =IF(A4="","",MONTH(A4)) -> 1
A5: 45663.603 | B5: Club Colombia | C5: Cerveza | D5: 1 | E5: 4000 | F5: 2600 | G5: Efectivo | H5: Andrea Bolívar | I5: =IF(A5="","",D5*E5) -> 4000 | J5: =IF(A5="","",D5*F5) -> 2600 | K5: =IF(A5="","",YEAR(A5)) -> 2025 | L5: =IF(A5="","",MONTH(A5)) -> 1
A6: 45663.724 | B6: Agua Cristal 600 ml | C6: Agua | D6: 1 | E6: 2000 | F6: 1100 | G6: Efectivo | H6: Andrea Bolívar | I6: =IF(A6="","",D6*E6) -> 2000 | J6: =IF(A6="","",D6*F6) -> 1100 | K6: =IF(A6="","",YEAR(A6)) -> 2025 | L6: =IF(A6="","",MONTH(A6)) -> 1
A7: 45663.785 | B7: Red Bull | C7: Energizantes | D7: 1 | E7: 7000 | F7: 4800 | G7: Efectivo | H7: Andrea Bolívar | I7: =IF(A7="","",D7*E7) -> 7000 | J7: =IF(A7="","",D7*F7) -> 4800 | K7: =IF(A7="","",YEAR(A7)) -> 2025 | L7: =IF(A7="","",MONTH(A7)) -> 1
A8: 45663.847 | B8: Coca-Cola 400 ml | C8: Gaseosas | D8: 2 | E8: 3000 | F8: 2000 | G8: Efectivo | H8: Carlos Perdomo | I8: =IF(A8="","",D8*E8) -> 6000 | J8: =IF(A8="","",D8*F8) -> 4000 | K8: =IF(A8="","",YEAR(A8)) -> 2025 | L8: =IF(A8="","",MONTH(A8)) -> 1
A9: 45664.362 | B9: Coca-Cola 400 ml | C9: Gaseosas | D9: 1 | E9: 3000 | F9: 2000 | G9: Efectivo | H9: Andrea Bolívar | I9: =IF(A9="","",D9*E9) -> 3000 | J9: =IF(A9="","",D9*F9) -> 2000 | K9: =IF(A9="","",YEAR(A9)) -> 2025 | L9: =IF(A9="","",MONTH(A9)) -> 1
A10: 45664.49 | B10: Club Colombia | C10: Cerveza | D10: 1 | E10: 4000 | F10: 2600 | G10: Efectivo | H10: Luisa Trujillo | I10: =IF(A10="","",D10*E10) -> 4000 | J10: =IF(A10="","",D10*F10) -> 2600 | K10: =IF(A10="","",YEAR(A10)) -> 2025 | L10: =IF(A10="","",MONTH(A10)) -> 1
A11: 45664.548 | B11: Agua Cristal 600 ml | C11: Agua | D11: 1 | E11: 2000 | F11: 1100 | G11: Transferencia | H11: Luisa Trujillo | I11: =IF(A11="","",D11*E11) -> 2000 | J11: =IF(A11="","",D11*F11) -> 1100 | K11: =IF(A11="","",YEAR(A11)) -> 2025 | L11: =IF(A11="","",MONTH(A11)) -> 1
A12: 45664.768 | B12: Coca-Cola 400 ml | C12: Gaseosas | D12: 1 | E12: 3000 | F12: 2000 | G12: Efectivo | H12: Luisa Trujillo | I12: =IF(A12="","",D12*E12) -> 3000 | J12: =IF(A12="","",D12*F12) -> 2000 | K12: =IF(A12="","",YEAR(A12)) -> 2025 | L12: =IF(A12="","",MONTH(A12)) -> 1
A13: 45664.892 | B13: Tinto | C13: Café | D13: 2 | E13: 1000 | F13: 300 | G13: Efectivo | H13: Carlos Perdomo | I13: =IF(A13="","",D13*E13) -> 2000 | J13: =IF(A13="","",D13*F13) -> 600 | K13: =IF(A13="","",YEAR(A13)) -> 2025 | L13: =IF(A13="","",MONTH(A13)) -> 1
... A1224: 46320.896 | B1224: Red Bull | C1224: Energizantes | D1224: 3 | E1224: 7000 | F1224: 4800 | G1224: Efectivo | H1224: Luisa Trujillo | I1224: =IF(A1224="","",D1224*E1224) -> 21000 | J1224: =IF(A1224="","",D1224*F1224) -> 14400 | K1224: =IF(A1224="","",YEAR(A1224)) -> 2026 | L1224: =IF(A1224="","",MONTH(A1224)) -> 10
I1225: =IF(A1225="","",D1225*E1225) | J1225: =IF(A1225="","",D1225*F1225) | K1225: =IF(A1225="","",YEAR(A1225)) | L1225: =IF(A1225="","",MONTH(A1225))
I1226: =IF(A1226="","",D1226*E1226) | J1226: =IF(A1226="","",D1226*F1226) | K1226: =IF(A1226="","",YEAR(A1226)) | L1226: =IF(A1226="","",MONTH(A1226))
I1227: =IF(A1227="","",D1227*E1227) | J1227: =IF(A1227="","",D1227*F1227) | K1227: =IF(A1227="","",YEAR(A1227)) | L1227: =IF(A1227="","",MONTH(A1227))
I1228: =IF(A1228="","",D1228*E1228) | J1228: =IF(A1228="","",D1228*F1228) | K1228: =IF(A1228="","",YEAR(A1228)) | L1228: =IF(A1228="","",MONTH(A1228))
I1229: =IF(A1229="","",D1229*E1229) | J1229: =IF(A1229="","",D1229*F1229) | K1229: =IF(A1229="","",YEAR(A1229)) | L1229: =IF(A1229="","",MONTH(A1229))
I1230: =IF(A1230="","",D1230*E1230) | J1230: =IF(A1230="","",D1230*F1230) | K1230: =IF(A1230="","",YEAR(A1230)) | L1230: =IF(A1230="","",MONTH(A1230))
I1231: =IF(A1231="","",D1231*E1231) | J1231: =IF(A1231="","",D1231*F1231) | K1231: =IF(A1231="","",YEAR(A1231)) | L1231: =IF(A1231="","",MONTH(A1231))
I1232: =IF(A1232="","",D1232*E1232) | J1232: =IF(A1232="","",D1232*F1232) | K1232: =IF(A1232="","",YEAR(A1232)) | L1232: =IF(A1232="","",MONTH(A1232))
I1233: =IF(A1233="","",D1233*E1233) | J1233: =IF(A1233="","",D1233*F1233) | K1233: =IF(A1233="","",YEAR(A1233)) | L1233: =IF(A1233="","",MONTH(A1233))
I1234: =IF(A1234="","",D1234*E1234) | J1234: =IF(A1234="","",D1234*F1234) | K1234: =IF(A1234="","",YEAR(A1234)) | L1234: =IF(A1234="","",MONTH(A1234))
I1235: =IF(A1235="","",D1235*E1235) | J1235: =IF(A1235="","",D1235*F1235) | K1235: =IF(A1235="","",YEAR(A1235)) | L1235: =IF(A1235="","",MONTH(A1235))
I1236: =IF(A1236="","",D1236*E1236) | J1236: =IF(A1236="","",D1236*F1236) | K1236: =IF(A1236="","",YEAR(A1236)) | L1236: =IF(A1236="","",MONTH(A1236))
... I5001: =IF(A5001="","",D5001*E5001) | J5001: =IF(A5001="","",D5001*F5001) | K5001: =IF(A5001="","",YEAR(A5001)) | L5001: =IF(A5001="","",MONTH(A5001))

Sheet Gastos
A1: Fecha | B1: Concepto | C1: Valor ($) | D1: Año | E1: Mes | G1: Columnas A a C: gastos del negocio. D y E se calculan solas.
A2: 45672 | B2: Luz y agua | C2: 187000 | D2: =IF(A2="","",YEAR(A2)) -> 2025 | E2: =IF(A2="","",MONTH(A2)) -> 1
A3: 45658 | B3: Arriendo | C3: 900000 | D3: =IF(A3="","",YEAR(A3)) -> 2025 | E3: =IF(A3="","",MONTH(A3)) -> 1
A4: 45703 | B4: Luz y agua | C4: 194000 | D4: =IF(A4="","",YEAR(A4)) -> 2025 | E4: =IF(A4="","",MONTH(A4)) -> 2
A5: 45689 | B5: Arriendo | C5: 900000 | D5: =IF(A5="","",YEAR(A5)) -> 2025 | E5: =IF(A5="","",MONTH(A5)) -> 2
A6: 45731 | B6: Luz y agua | C6: 201000 | D6: =IF(A6="","",YEAR(A6)) -> 2025 | E6: =IF(A6="","",MONTH(A6)) -> 3
A7: 45717 | B7: Arriendo | C7: 900000 | D7: =IF(A7="","",YEAR(A7)) -> 2025 | E7: =IF(A7="","",MONTH(A7)) -> 3
A8: 45762 | B8: Luz y agua | C8: 208000 | D8: =IF(A8="","",YEAR(A8)) -> 2025 | E8: =IF(A8="","",MONTH(A8)) -> 4
A9: 45748 | B9: Arriendo | C9: 900000 | D9: =IF(A9="","",YEAR(A9)) -> 2025 | E9: =IF(A9="","",MONTH(A9)) -> 4
A10: 45792 | B10: Luz y agua | C10: 215000 | D10: =IF(A10="","",YEAR(A10)) -> 2025 | E10: =IF(A10="","",MONTH(A10)) -> 5
A11: 45778 | B11: Arriendo | C11: 900000 | D11: =IF(A11="","",YEAR(A11)) -> 2025 | E11: =IF(A11="","",MONTH(A11)) -> 5
A12: 45823 | B12: Luz y agua | C12: 222000 | D12: =IF(A12="","",YEAR(A12)) -> 2025 | E12: =IF(A12="","",MONTH(A12)) -> 6
A13: 45809 | B13: Arriendo | C13: 900000 | D13: =IF(A13="","",YEAR(A13)) -> 2025 | E13: =IF(A13="","",MONTH(A13)) -> 6
... A45: 46296 | B45: Arriendo | C45: 900000 | D45: =IF(A45="","",YEAR(A45)) -> 2026 | E45: =IF(A45="","",MONTH(A45)) -> 10
D46: =IF(A46="","",YEAR(A46)) | E46: =IF(A46="","",MONTH(A46))
D47: =IF(A47="","",YEAR(A47)) | E47: =IF(A47="","",MONTH(A47))
D48: =IF(A48="","",YEAR(A48)) | E48: =IF(A48="","",MONTH(A48))
D49: =IF(A49="","",YEAR(A49)) | E49: =IF(A49="","",MONTH(A49))
D50: =IF(A50="","",YEAR(A50)) | E50: =IF(A50="","",MONTH(A50))
D51: =IF(A51="","",YEAR(A51)) | E51: =IF(A51="","",MONTH(A51))
D52: =IF(A52="","",YEAR(A52)) | E52: =IF(A52="","",MONTH(A52))
D53: =IF(A53="","",YEAR(A53)) | E53: =IF(A53="","",MONTH(A53))
D54: =IF(A54="","",YEAR(A54)) | E54: =IF(A54="","",MONTH(A54))
D55: =IF(A55="","",YEAR(A55)) | E55: =IF(A55="","",MONTH(A55))
D56: =IF(A56="","",YEAR(A56)) | E56: =IF(A56="","",MONTH(A56))
D57: =IF(A57="","",YEAR(A57)) | E57: =IF(A57="","",MONTH(A57))
... D1001: =IF(A1001="","",YEAR(A1001)) | E1001: =IF(A1001="","",MONTH(A1001))

Sheet Cálculos
A1: Cálculos del tablero (no se edita: todo sale de las hojas de datos y de los filtros)
D2: Indicador | E2: Valor
A3: Año | B3: =Tablero!B5 -> 2026 | D3: Ingresos parqueo | E3: =SUMIFS(Cobros!$F$2:$F$5001,Cobros!$J$2:$J$5001,$B$3,Cobros!$K$2:$K$5001,">="&$B$4,Cobros!$K$2:$K$5001,"<="&$B$5,Cobros!$H$2:$H$5001,$B$6) -> 7889687
A4: Mes desde | B4: =IF(Tablero!B8="Todos",1,MATCH(Tablero!B8,Listas!$A$2:$A$13,0)) -> 1 | D4: Vehículos atendidos | E4: =COUNTIFS(Cobros!$J$2:$J$5001,$B$3,Cobros!$K$2:$K$5001,">="&$B$4,Cobros!$K$2:$K$5001,"<="&$B$5,Cobros!$H$2:$H$5001,$B$6) -> 1150
A5: Mes hasta | B5: =IF(Tablero!B8="Todos",12,B4) -> 12 | D5: Ventas tienda | E5: =SUMIFS(Ventas!$I$2:$I$5001,Ventas!$K$2:$K$5001,$B$3,Ventas!$L$2:$L$5001,">="&$B$4,Ventas!$L$2:$L$5001,"<="&$B$5,Ventas!$H$2:$H$5001,$B$6) -> 2944000
A6: Trabajador | B6: =IF(Tablero!B11="Todos","*",Tablero!B11) -> * | D6: Costo tienda | E6: =SUMIFS(Ventas!$J$2:$J$5001,Ventas!$K$2:$K$5001,$B$3,Ventas!$L$2:$L$5001,">="&$B$4,Ventas!$L$2:$L$5001,"<="&$B$5,Ventas!$H$2:$H$5001,$B$6) -> 1881700
A7: Mes anterior (n°) | B7: =IF(Tablero!B8="Todos",0,B4-1) -> 0 | D7: Número de ventas | E7: =COUNTIFS(Ventas!$K$2:$K$5001,$B$3,Ventas!$L$2:$L$5001,">="&$B$4,Ventas!$L$2:$L$5001,"<="&$B$5,Ventas!$H$2:$H$5001,$B$6) -> 572
A8: Días del periodo | B8: =IF(Tablero!B8="Todos",IF(B3=YEAR(TODAY()),TODAY()-DATE(B3,1,1)+1,365),DAY(DATE(B3,B4+1,0))) -> 294 | D8: Minutos totales | E8: =SUMIFS(Cobros!$E$2:$E$5001,Cobros!$J$2:$J$5001,$B$3,Cobros!$K$2:$K$5001,">="&$B$4,Cobros!$K$2:$K$5001,"<="&$B$5,Cobros!$H$2:$H$5001,$B$6) -> 259267
D9: Visitas de primera vez | E9: =COUNTIFS(Cobros!$J$2:$J$5001,$B$3,Cobros!$K$2:$K$5001,">="&$B$4,Cobros!$K$2:$K$5001,"<="&$B$5,Cobros!$H$2:$H$5001,$B$6,Cobros!$M$2:$M$5001,1) -> 158
D10: Gastos | E10: =IF($B$6="*",SUMIFS(Gastos!$C$2:$C$1001,Gastos!$D$2:$D$1001,$B$3,Gastos!$E$2:$E$1001,">="&$B$4,Gastos!$E$2:$E$1001,"<="&$B$5),0) -> 11185000
D11: Ingresos periodo anterior | E11: =IF($B$7=0,0,SUMIFS(Cobros!$F$2:$F$5001,Cobros!$J$2:$J$5001,$B$3,Cobros!$K$2:$K$5001,$B$7,Cobros!$H$2:$H$5001,$B$6)+SUMIFS(Ventas!$I$2:$I$5001,Ventas!$K$2:$K$5001,$B$3,Ventas!$L$2:$L$5001,$B$7,Ventas!$H$2:$H$5001,$B$6)) -> 0
A14: Por mes (año completo, con el filtro de trabajador) | N14: Ingresos por vehículo | Q14: Cómo pagan (parqueo + tienda) | T14: Cómo entran (vehículos)
A15: Mes | B15: N° | C15: Vehículos | D15: Ingresos parqueo | E15: Ventas tienda | F15: Ingresos totales | G15: Costo tienda | H15: Gastos | I15: Crecimiento % | J15: Primera vez | K15: Vuelven | L15: Cobro promedio | N15: Nombre | O15: Valor | Q15: Nombre | R15: Valor | T15: Nombre | U15: Valor
A16: Ene | B16: 1 | C16: =COUNTIFS(Cobros!$J$2:$J$5001,$B$3,Cobros!$K$2:$K$5001,$B16,Cobros!$H$2:$H$5001,$B$6) -> 115 | D16: =SUMIFS(Cobros!$F$2:$F$5001,Cobros!$J$2:$J$5001,$B$3,Cobros!$K$2:$K$5001,$B16,Cobros!$H$2:$H$5001,$B$6) -> 804137 | E16: =SUMIFS(Ventas!$I$2:$I$5001,Ventas!$K$2:$K$5001,$B$3,Ventas!$L$2:$L$5001,$B16,Ventas!$H$2:$H$5001,$B$6) -> 329500 | F16: =D16+E16 -> 1133637 | G16: =SUMIFS(Ventas!$J$2:$J$5001,Ventas!$K$2:$K$5001,$B$3,Ventas!$L$2:$L$5001,$B16,Ventas!$H$2:$H$5001,$B$6) -> 214600 | H16: =IF($B$6="*",SUMIFS(Gastos!$C$2:$C$1001,Gastos!$D$2:$D$1001,$B$3,Gastos!$E$2:$E$1001,$B16),0) -> 1087000 | I16: =0 -> 0 | J16: =COUNTIFS(Cobros!$J$2:$J$5001,$B$3,Cobros!$K$2:$K$5001,$B16,Cobros!$H$2:$H$5001,$B$6,Cobros!$M$2:$M$5001,1) -> 79 | K16: =C16-J16 -> 36 | L16: =IF(C16=0,0,D16/C16) -> 6992.4957 | N16: Carro | O16: =SUMIFS(Cobros!$F$2:$F$5001,Cobros!$J$2:$J$5001,$B$3,Cobros!$K$2:$K$5001,">="&$B$4,Cobros!$K$2:$K$5001,"<="&$B$5,Cobros!$H$2:$H$5001,$B$6,Cobros!$D$2:$D$5001,N16) -> 4671100 | Q16: Efectivo | R16: =SUMIFS(Cobros!$F$2:$F$5001,Cobros!$J$2:$J$5001,$B$3,Cobros!$K$2:$K$5001,">="&$B$4,Cobros!$K$2:$K$5001,"<="&$B$5,Cobros!$H$2:$H$5001,$B$6,Cobros!$G$2:$G$5001,Q16)+SUMIFS(Ventas!$I$2:$I$5001,Ventas!$K$2:$K$5001,$B$3,Ventas!$L$2:$L$5001,">="&$B$4,Ventas!$L$2:$L$5001,"<="&$B$5,Ventas!$H$2:$H$5001,$B$6,Ventas!$G$2:$G$5001,Q16) -> 6780600 | T16: Por tiempo | U16: =COUNTIFS(Cobros!$J$2:$J$5001,$B$3,Cobros!$K$2:$K$5001,">="&$B$4,Cobros!$K$2:$K$5001,"<="&$B$5,Cobros!$H$2:$H$5001,$B$6,Cobros!$I$2:$I$5001,T16) -> 926
A17: Feb | B17: 2 | C17: =COUNTIFS(Cobros!$J$2:$J$5001,$B$3,Cobros!$K$2:$K$5001,$B17,Cobros!$H$2:$H$5001,$B$6) -> 165 | D17: =SUMIFS(Cobros!$F$2:$F$5001,Cobros!$J$2:$J$5001,$B$3,Cobros!$K$2:$K$5001,$B17,Cobros!$H$2:$H$5001,$B$6) -> 1131350 | E17: =SUMIFS(Ventas!$I$2:$I$5001,Ventas!$K$2:$K$5001,$B$3,Ventas!$L$2:$L$5001,$B17,Ventas!$H$2:$H$5001,$B$6) -> 413500 | F17: =D17+E17 -> 1544850 | G17: =SUMIFS(Ventas!$J$2:$J$5001,Ventas!$K$2:$K$5001,$B$3,Ventas!$L$2:$L$5001,$B17,Ventas!$H$2:$H$5001,$B$6) -> 260600 | H17: =IF($B$6="*",SUMIFS(Gastos!$C$2:$C$1001,Gastos!$D$2:$D$1001,$B$3,Gastos!$E$2:$E$1001,$B17),0) -> 1094000 | I17: =IF(OR(F17=0,F16=0),0,(F17-F16)/F16) -> 0.36273781 | J17: =COUNTIFS(Cobros!$J$2:$J$5001,$B$3,Cobros!$K$2:$K$5001,$B17,Cobros!$H$2:$H$5001,$B$6,Cobros!$M$2:$M$5001,1) -> 43 | K17: =C17-J17 -> 122 | L17: =IF(C17=0,0,D17/C17) -> 6856.6667 | N17: Moto | O17: =SUMIFS(Cobros!$F$2:$F$5001,Cobros!$J$2:$J$5001,$B$3,Cobros!$K$2:$K$5001,">="&$B$4,Cobros!$K$2:$K$5001,"<="&$B$5,Cobros!$H$2:$H$5001,$B$6,Cobros!$D$2:$D$5001,N17) -> 1187500 | Q17: Transferencia | R17: =SUMIFS(Cobros!$F$2:$F$5001,Cobros!$J$2:$J$5001,$B$3,Cobros!$K$2:$K$5001,">="&$B$4,Cobros!$K$2:$K$5001,"<="&$B$5,Cobros!$H$2:$H$5001,$B$6,Cobros!$G$2:$G$5001,Q17)+SUMIFS(Ventas!$I$2:$I$5001,Ventas!$K$2:$K$5001,$B$3,Ventas!$L$2:$L$5001,">="&$B$4,Ventas!$L$2:$L$5001,"<="&$B$5,Ventas!$H$2:$H$5001,$B$6,Ventas!$G$2:$G$5001,Q17) -> 2628137 | T17: Convenio | U17: =COUNTIFS(Cobros!$J$2:$J$5001,$B$3,Cobros!$K$2:$K$5001,">="&$B$4,Cobros!$K$2:$K$5001,"<="&$B$5,Cobros!$H$2:$H$5001,$B$6,Cobros!$I$2:$I$5001,T17) -> 116
A18: Mar | B18: 3 | C18: =COUNTIFS(Cobros!$J$2:$J$5001,$B$3,Cobros!$K$2:$K$5001,$B18,Cobros!$H$2:$H$5001,$B$6) -> 90 | D18: =SUMIFS(Cobros!$F$2:$F$5001,Cobros!$J$2:$J$5001,$B$3,Cobros!$K$2:$K$5001,$B18,Cobros!$H$2:$H$5001,$B$6) -> 656075 | E18: =SUMIFS(Ventas!$I$2:$I$5001,Ventas!$K$2:$K$5001,$B$3,Ventas!$L$2:$L$5001,$B18,Ventas!$H$2:$H$5001,$B$6) -> 217500 | F18: =D18+E18 -> 873575 | G18: =SUMIFS(Ventas!$J$2:$J$5001,Ventas!$K$2:$K$5001,$B$3,Ventas!$L$2:$L$5001,$B18,Ventas!$H$2:$H$5001,$B$6) -> 136800 | H18: =IF($B$6="*",SUMIFS(Gastos!$C$2:$C$1001,Gastos!$D$2:$D$1001,$B$3,Gastos!$E$2:$E$1001,$B18),0) -> 1101000 | I18: =IF(OR(F18=0,F17=0),0,(F18-F17)/F17) -> -0.43452439 | J18: =COUNTIFS(Cobros!$J$2:$J$5001,$B$3,Cobros!$K$2:$K$5001,$B18,Cobros!$H$2:$H$5001,$B$6,Cobros!$M$2:$M$5001,1) -> 10 | K18: =C18-J18 -> 80 | L18: =IF(C18=0,0,D18/C18) -> 7289.7222 | N18: Bus | O18: =SUMIFS(Cobros!$F$2:$F$5001,Cobros!$J$2:$J$5001,$B$3,Cobros!$K$2:$K$5001,">="&$B$4,Cobros!$K$2:$K$5001,"<="&$B$5,Cobros!$H$2:$H$5001,$B$6,Cobros!$D$2:$D$5001,N18) -> 929325 | Q18: Dividido | R18: =SUMIFS(Cobros!$F$2:$F$5001,Cobros!$J$2:$J$5001,$B$3,Cobros!$K$2:$K$5001,">="&$B$4,Cobros!$K$2:$K$5001,"<="&$B$5,Cobros!$H$2:$H$5001,$B$6,Cobros!$G$2:$G$5001,Q18)+SUMIFS(Ventas!$I$2:$I$5001,Ventas!$K$2:$K$5001,$B$3,Ventas!$L$2:$L$5001,">="&$B$4,Ventas!$L$2:$L$5001,"<="&$B$5,Ventas!$H$2:$H$5001,$B$6,Ventas!$G$2:$G$5001,Q18) -> 628675 | T18: Mensualidad | U18: =COUNTIFS(Cobros!$J$2:$J$5001,$B$3,Cobros!$K$2:$K$5001,">="&$B$4,Cobros!$K$2:$K$5001,"<="&$B$5,Cobros!$H$2:$H$5001,$B$6,Cobros!$I$2:$I$5001,T18) -> 108
A19: Abr | B19: 4 | C19: =COUNTIFS(Cobros!$J$2:$J$5001,$B$3,Cobros!$K$2:$K$5001,$B19,Cobros!$H$2:$H$5001,$B$6) -> 140 | D19: =SUMIFS(Cobros!$F$2:$F$5001,Cobros!$J$2:$J$5001,$B$3,Cobros!$K$2:$K$5001,$B19,Cobros!$H$2:$H$5001,$B$6) -> 888425 | E19: =SUMIFS(Ventas!$I$2:$I$5001,Ventas!$K$2:$K$5001,$B$3,Ventas!$L$2:$L$5001,$B19,Ventas!$H$2:$H$5001,$B$6) -> 370000 | F19: =D19+E19 -> 1258425 | G19: =SUMIFS(Ventas!$J$2:$J$5001,Ventas!$K$2:$K$5001,$B$3,Ventas!$L$2:$L$5001,$B19,Ventas!$H$2:$H$5001,$B$6) -> 237900 | H19: =IF($B$6="*",SUMIFS(Gastos!$C$2:$C$1001,Gastos!$D$2:$D$1001,$B$3,Gastos!$E$2:$E$1001,$B19),0) -> 1108000 | I19: =IF(OR(F19=0,F18=0),0,(F19-F18)/F18) -> 0.44054603 | J19: =COUNTIFS(Cobros!$J$2:$J$5001,$B$3,Cobros!$K$2:$K$5001,$B19,Cobros!$H$2:$H$5001,$B$6,Cobros!$M$2:$M$5001,1) -> 7 | K19: =C19-J19 -> 133 | L19: =IF(C19=0,0,D19/C19) -> 6345.8929 | N19: Tractomula | O19: =SUMIFS(Cobros!$F$2:$F$5001,Cobros!$J$2:$J$5001,$B$3,Cobros!$K$2:$K$5001,">="&$B$4,Cobros!$K$2:$K$5001,"<="&$B$5,Cobros!$H$2:$H$5001,$B$6,Cobros!$D$2:$D$5001,N19) -> 785100 | Q19: Fiado | R19: =SUMIFS(Cobros!$F$2:$F$5001,Cobros!$J$2:$J$5001,$B$3,Cobros!$K$2:$K$5001,">="&$B$4,Cobros!$K$2:$K$5001,"<="&$B$5,Cobros!$H$2:$H$5001,$B$6,Cobros!$G$2:$G$5001,Q19)+SUMIFS(Ventas!$I$2:$I$5001,Ventas!$K$2:$K$5001,$B$3,Ventas!$L$2:$L$5001,">="&$B$4,Ventas!$L$2:$L$5001,"<="&$B$5,Ventas!$H$2:$H$5001,$B$6,Ventas!$G$2:$G$5001,Q19) -> 368475
A20: May | B20: 5 | C20: =COUNTIFS(Cobros!$J$2:$J$5001,$B$3,Cobros!$K$2:$K$5001,$B20,Cobros!$H$2:$H$5001,$B$6) -> 65 | D20: =SUMIFS(Cobros!$F$2:$F$5001,Cobros!$J$2:$J$5001,$B$3,Cobros!$K$2:$K$5001,$B20,Cobros!$H$2:$H$5001,$B$6) -> 430050 | E20: =SUMIFS(Ventas!$I$2:$I$5001,Ventas!$K$2:$K$5001,$B$3,Ventas!$L$2:$L$5001,$B20,Ventas!$H$2:$H$5001,$B$6) -> 185500 | F20: =D20+E20 -> 615550 | G20: =SUMIFS(Ventas!$J$2:$J$5001,Ventas!$K$2:$K$5001,$B$3,Ventas!$L$2:$L$5001,$B20,Ventas!$H$2:$H$5001,$B$6) -> 120400 | H20: =IF($B$6="*",SUMIFS(Gastos!$C$2:$C$1001,Gastos!$D$2:$D$1001,$B$3,Gastos!$E$2:$E$1001,$B20),0) -> 1115000 | I20: =IF(OR(F20=0,F19=0),0,(F20-F19)/F19) -> -0.51085682 | J20: =COUNTIFS(Cobros!$J$2:$J$5001,$B$3,Cobros!$K$2:$K$5001,$B20,Cobros!$H$2:$H$5001,$B$6,Cobros!$M$2:$M$5001,1) -> 3 | K20: =C20-J20 -> 62 | L20: =IF(C20=0,0,D20/C20) -> 6616.1538 | N20: Chiva | O20: =SUMIFS(Cobros!$F$2:$F$5001,Cobros!$J$2:$J$5001,$B$3,Cobros!$K$2:$K$5001,">="&$B$4,Cobros!$K$2:$K$5001,"<="&$B$5,Cobros!$H$2:$H$5001,$B$6,Cobros!$D$2:$D$5001,N20) -> 316662 | Q20: Monedero | R20: =SUMIFS(Cobros!$F$2:$F$5001,Cobros!$J$2:$J$5001,$B$3,Cobros!$K$2:$K$5001,">="&$B$4,Cobros!$K$2:$K$5001,"<="&$B$5,Cobros!$H$2:$H$5001,$B$6,Cobros!$G$2:$G$5001,Q20)+SUMIFS(Ventas!$I$2:$I$5001,Ventas!$K$2:$K$5001,$B$3,Ventas!$L$2:$L$5001,">="&$B$4,Ventas!$L$2:$L$5001,"<="&$B$5,Ventas!$H$2:$H$5001,$B$6,Ventas!$G$2:$G$5001,Q20) -> 427800
A21: Jun | B21: 6 | C21: =COUNTIFS(Cobros!$J$2:$J$5001,$B$3,Cobros!$K$2:$K$5001,$B21,Cobros!$H$2:$H$5001,$B$6) -> 115 | D21: =SUMIFS(Cobros!$F$2:$F$5001,Cobros!$J$2:$J$5001,$B$3,Cobros!$K$2:$K$5001,$B21,Cobros!$H$2:$H$5001,$B$6) -> 865525 | E21: =SUMIFS(Ventas!$I$2:$I$5001,Ventas!$K$2:$K$5001,$B$3,Ventas!$L$2:$L$5001,$B21,Ventas!$H$2:$H$5001,$B$6) -> 276000 | F21: =D21+E21 -> 1141525 | G21: =SUMIFS(Ventas!$J$2:$J$5001,Ventas!$K$2:$K$5001,$B$3,Ventas!$L$2:$L$5001,$B21,Ventas!$H$2:$H$5001,$B$6) -> 170500 | H21: =IF($B$6="*",SUMIFS(Gastos!$C$2:$C$1001,Gastos!$D$2:$D$1001,$B$3,Gastos!$E$2:$E$1001,$B21),0) -> 1122000 | I21: =IF(OR(F21=0,F20=0),0,(F21-F20)/F20) -> 0.85447973 | J21: =COUNTIFS(Cobros!$J$2:$J$5001,$B$3,Cobros!$K$2:$K$5001,$B21,Cobros!$H$2:$H$5001,$B$6,Cobros!$M$2:$M$5001,1) -> 5 | K21: =C21-J21 -> 110 | L21: =IF(C21=0,0,D21/C21) -> 7526.3043
A22: Jul | B22: 7 | C22: =COUNTIFS(Cobros!$J$2:$J$5001,$B$3,Cobros!$K$2:$K$5001,$B22,Cobros!$H$2:$H$5001,$B$6) -> 165 | D22: =SUMIFS(Cobros!$F$2:$F$5001,Cobros!$J$2:$J$5001,$B$3,Cobros!$K$2:$K$5001,$B22,Cobros!$H$2:$H$5001,$B$6) -> 1064675 | E22: =SUMIFS(Ventas!$I$2:$I$5001,Ventas!$K$2:$K$5001,$B$3,Ventas!$L$2:$L$5001,$B22,Ventas!$H$2:$H$5001,$B$6) -> 380000 | F22: =D22+E22 -> 1444675 | G22: =SUMIFS(Ventas!$J$2:$J$5001,Ventas!$K$2:$K$5001,$B$3,Ventas!$L$2:$L$5001,$B22,Ventas!$H$2:$H$5001,$B$6) -> 241900 | H22: =IF($B$6="*",SUMIFS(Gastos!$C$2:$C$1001,Gastos!$D$2:$D$1001,$B$3,Gastos!$E$2:$E$1001,$B22),0) -> 1129000 | I22: =IF(OR(F22=0,F21=0),0,(F22-F21)/F21) -> 0.2655658 | J22: =COUNTIFS(Cobros!$J$2:$J$5001,$B$3,Cobros!$K$2:$K$5001,$B22,Cobros!$H$2:$H$5001,$B$6,Cobros!$M$2:$M$5001,1) -> 4 | K22: =C22-J22 -> 161 | L22: =IF(C22=0,0,D22/C22) -> 6452.5758
A23: Ago | B23: 8 | C23: =COUNTIFS(Cobros!$J$2:$J$5001,$B$3,Cobros!$K$2:$K$5001,$B23,Cobros!$H$2:$H$5001,$B$6) -> 90 | D23: =SUMIFS(Cobros!$F$2:$F$5001,Cobros!$J$2:$J$5001,$B$3,Cobros!$K$2:$K$5001,$B23,Cobros!$H$2:$H$5001,$B$6) -> 630450 | E23: =SUMIFS(Ventas!$I$2:$I$5001,Ventas!$K$2:$K$5001,$B$3,Ventas!$L$2:$L$5001,$B23,Ventas!$H$2:$H$5001,$B$6) -> 246000 | F23: =D23+E23 -> 876450 | G23: =SUMIFS(Ventas!$J$2:$J$5001,Ventas!$K$2:$K$5001,$B$3,Ventas!$L$2:$L$5001,$B23,Ventas!$H$2:$H$5001,$B$6) -> 158300 | H23: =IF($B$6="*",SUMIFS(Gastos!$C$2:$C$1001,Gastos!$D$2:$D$1001,$B$3,Gastos!$E$2:$E$1001,$B23),0) -> 1136000 | I23: =IF(OR(F23=0,F22=0),0,(F23-F22)/F22) -> -0.39332376 | J23: =COUNTIFS(Cobros!$J$2:$J$5001,$B$3,Cobros!$K$2:$K$5001,$B23,Cobros!$H$2:$H$5001,$B$6,Cobros!$M$2:$M$5001,1) -> 4 | K23: =C23-J23 -> 86 | L23: =IF(C23=0,0,D23/C23) -> 7005 | N23: Ingresos por trabajador | Q23: Tienda por categoría
A24: Sep | B24: 9 | C24: =COUNTIFS(Cobros!$J$2:$J$5001,$B$3,Cobros!$K$2:$K$5001,$B24,Cobros!$H$2:$H$5001,$B$6) -> 140 | D24: =SUMIFS(Cobros!$F$2:$F$5001,Cobros!$J$2:$J$5001,$B$3,Cobros!$K$2:$K$5001,$B24,Cobros!$H$2:$H$5001,$B$6) -> 971400 | E24: =SUMIFS(Ventas!$I$2:$I$5001,Ventas!$K$2:$K$5001,$B$3,Ventas!$L$2:$L$5001,$B24,Ventas!$H$2:$H$5001,$B$6) -> 362000 | F24: =D24+E24 -> 1333400 | G24: =SUMIFS(Ventas!$J$2:$J$5001,Ventas!$K$2:$K$5001,$B$3,Ventas!$L$2:$L$5001,$B24,Ventas!$H$2:$H$5001,$B$6) -> 235000 | H24: =IF($B$6="*",SUMIFS(Gastos!$C$2:$C$1001,Gastos!$D$2:$D$1001,$B$3,Gastos!$E$2:$E$1001,$B24),0) -> 1143000 | I24: =IF(OR(F24=0,F23=0),0,(F24-F23)/F23) -> 0.5213646 | J24: =COUNTIFS(Cobros!$J$2:$J$5001,$B$3,Cobros!$K$2:$K$5001,$B24,Cobros!$H$2:$H$5001,$B$6,Cobros!$M$2:$M$5001,1) -> 2 | K24: =C24-J24 -> 138 | L24: =IF(C24=0,0,D24/C24) -> 6938.5714 | N24: Nombre | O24: Valor | Q24: Nombre | R24: Valor
A25: Oct | B25: 10 | C25: =COUNTIFS(Cobros!$J$2:$J$5001,$B$3,Cobros!$K$2:$K$5001,$B25,Cobros!$H$2:$H$5001,$B$6) -> 65 | D25: =SUMIFS(Cobros!$F$2:$F$5001,Cobros!$J$2:$J$5001,$B$3,Cobros!$K$2:$K$5001,$B25,Cobros!$H$2:$H$5001,$B$6) -> 447600 | E25: =SUMIFS(Ventas!$I$2:$I$5001,Ventas!$K$2:$K$5001,$B$3,Ventas!$L$2:$L$5001,$B25,Ventas!$H$2:$H$5001,$B$6) -> 164000 | F25: =D25+E25 -> 611600 | G25: =SUMIFS(Ventas!$J$2:$J$5001,Ventas!$K$2:$K$5001,$B$3,Ventas!$L$2:$L$5001,$B25,Ventas!$H$2:$H$5001,$B$6) -> 105700 | H25: =IF($B$6="*",SUMIFS(Gastos!$C$2:$C$1001,Gastos!$D$2:$D$1001,$B$3,Gastos!$E$2:$E$1001,$B25),0) -> 1150000 | I25: =IF(OR(F25=0,F24=0),0,(F25-F24)/F24) -> -0.54132293 | J25: =COUNTIFS(Cobros!$J$2:$J$5001,$B$3,Cobros!$K$2:$K$5001,$B25,Cobros!$H$2:$H$5001,$B$6,Cobros!$M$2:$M$5001,1) -> 1 | K25: =C25-J25 -> 64 | L25: =IF(C25=0,0,D25/C25) -> 6886.1538 | N25: =IF(Listas!D3="","",Listas!D3) -> Andrea Bolívar | O25: =SUMIFS(Cobros!$F$2:$F$5001,Cobros!$J$2:$J$5001,$B$3,Cobros!$K$2:$K$5001,">="&$B$4,Cobros!$K$2:$K$5001,"<="&$B$5,Cobros!$H$2:$H$5001,N25)+SUMIFS(Ventas!$I$2:$I$5001,Ventas!$K$2:$K$5001,$B$3,Ventas!$L$2:$L$5001,">="&$B$4,Ventas!$L$2:$L$5001,"<="&$B$5,Ventas!$H$2:$H$5001,N25) -> 3567050 | Q25: =IF(Listas!F2="","",Listas!F2) -> Agua | R25: =SUMIFS(Ventas!$I$2:$I$5001,Ventas!$K$2:$K$5001,$B$3,Ventas!$L$2:$L$5001,">="&$B$4,Ventas!$L$2:$L$5001,"<="&$B$5,Ventas!$H$2:$H$5001,$B$6,Ventas!$C$2:$C$5001,Q25) -> 192000
A26: Nov | B26: 11 | C26: =COUNTIFS(Cobros!$J$2:$J$5001,$B$3,Cobros!$K$2:$K$5001,$B26,Cobros!$H$2:$H$5001,$B$6) -> 0 | D26: =SUMIFS(Cobros!$F$2:$F$5001,Cobros!$J$2:$J$5001,$B$3,Cobros!$K$2:$K$5001,$B26,Cobros!$H$2:$H$5001,$B$6) -> 0 | E26: =SUMIFS(Ventas!$I$2:$I$5001,Ventas!$K$2:$K$5001,$B$3,Ventas!$L$2:$L$5001,$B26,Ventas!$H$2:$H$5001,$B$6) -> 0 | F26: =D26+E26 -> 0 | G26: =SUMIFS(Ventas!$J$2:$J$5001,Ventas!$K$2:$K$5001,$B$3,Ventas!$L$2:$L$5001,$B26,Ventas!$H$2:$H$5001,$B$6) -> 0 | H26: =IF($B$6="*",SUMIFS(Gastos!$C$2:$C$1001,Gastos!$D$2:$D$1001,$B$3,Gastos!$E$2:$E$1001,$B26),0) -> 0 | I26: =IF(OR(F26=0,F25=0),0,(F26-F25)/F25) -> 0 | J26: =COUNTIFS(Cobros!$J$2:$J$5001,$B$3,Cobros!$K$2:$K$5001,$B26,Cobros!$H$2:$H$5001,$B$6,Cobros!$M$2:$M$5001,1) -> 0 | K26: =C26-J26 -> 0 | L26: =IF(C26=0,0,D26/C26) -> 0 | N26: =IF(Listas!D4="","",Listas!D4) -> Carlos Perdomo | O26: =SUMIFS(Cobros!$F$2:$F$5001,Cobros!$J$2:$J$5001,$B$3,Cobros!$K$2:$K$5001,">="&$B$4,Cobros!$K$2:$K$5001,"<="&$B$5,Cobros!$H$2:$H$5001,N26)+SUMIFS(Ventas!$I$2:$I$5001,Ventas!$K$2:$K$5001,$B$3,Ventas!$L$2:$L$5001,">="&$B$4,Ventas!$L$2:$L$5001,"<="&$B$5,Ventas!$H$2:$H$5001,N26) -> 3429625 | Q26: =IF(Listas!F3="","",Listas!F3) -> Bebidas | R26: =SUMIFS(Ventas!$I$2:$I$5001,Ventas!$K$2:$K$5001,$B$3,Ventas!$L$2:$L$5001,">="&$B$4,Ventas!$L$2:$L$5001,"<="&$B$5,Ventas!$H$2:$H$5001,$B$6,Ventas!$C$2:$C$5001,Q26) -> 486000
A27: Dic | B27: 12 | C27: =COUNTIFS(Cobros!$J$2:$J$5001,$B$3,Cobros!$K$2:$K$5001,$B27,Cobros!$H$2:$H$5001,$B$6) -> 0 | D27: =SUMIFS(Cobros!$F$2:$F$5001,Cobros!$J$2:$J$5001,$B$3,Cobros!$K$2:$K$5001,$B27,Cobros!$H$2:$H$5001,$B$6) -> 0 | E27: =SUMIFS(Ventas!$I$2:$I$5001,Ventas!$K$2:$K$5001,$B$3,Ventas!$L$2:$L$5001,$B27,Ventas!$H$2:$H$5001,$B$6) -> 0 | F27: =D27+E27 -> 0 | G27: =SUMIFS(Ventas!$J$2:$J$5001,Ventas!$K$2:$K$5001,$B$3,Ventas!$L$2:$L$5001,$B27,Ventas!$H$2:$H$5001,$B$6) -> 0 | H27: =IF($B$6="*",SUMIFS(Gastos!$C$2:$C$1001,Gastos!$D$2:$D$1001,$B$3,Gastos!$E$2:$E$1001,$B27),0) -> 0 | I27: =IF(OR(F27=0,F26=0),0,(F27-F26)/F26) -> 0 | J27: =COUNTIFS(Cobros!$J$2:$J$5001,$B$3,Cobros!$K$2:$K$5001,$B27,Cobros!$H$2:$H$5001,$B$6,Cobros!$M$2:$M$5001,1) -> 0 | K27: =C27-J27 -> 0 | L27: =IF(C27=0,0,D27/C27) -> 0 | N27: =IF(Listas!D5="","",Listas!D5) -> Luisa Trujillo | O27: =SUMIFS(Cobros!$F$2:$F$5001,Cobros!$J$2:$J$5001,$B$3,Cobros!$K$2:$K$5001,">="&$B$4,Cobros!$K$2:$K$5001,"<="&$B$5,Cobros!$H$2:$H$5001,N27)+SUMIFS(Ventas!$I$2:$I$5001,Ventas!$K$2:$K$5001,$B$3,Ventas!$L$2:$L$5001,">="&$B$4,Ventas!$L$2:$L$5001,"<="&$B$5,Ventas!$H$2:$H$5001,N27) -> 3837012 | Q27: =IF(Listas!F4="","",Listas!F4) -> Café | R27: =SUMIFS(Ventas!$I$2:$I$5001,Ventas!$K$2:$K$5001,$B$3,Ventas!$L$2:$L$5001,">="&$B$4,Ventas!$L$2:$L$5001,"<="&$B$5,Ventas!$H$2:$H$5001,$B$6,Ventas!$C$2:$C$5001,Q27) -> 89000
N28: =IF(Listas!D6="","",Listas!D6) | O28: =SUMIFS(Cobros!$F$2:$F$5001,Cobros!$J$2:$J$5001,$B$3,Cobros!$K$2:$K$5001,">="&$B$4,Cobros!$K$2:$K$5001,"<="&$B$5,Cobros!$H$2:$H$5001,N28)+SUMIFS(Ventas!$I$2:$I$5001,Ventas!$K$2:$K$5001,$B$3,Ventas!$L$2:$L$5001,">="&$B$4,Ventas!$L$2:$L$5001,"<="&$B$5,Ventas!$H$2:$H$5001,N28) -> 0 | Q28: =IF(Listas!F5="","",Listas!F5) -> Cerveza | R28: =SUMIFS(Ventas!$I$2:$I$5001,Ventas!$K$2:$K$5001,$B$3,Ventas!$L$2:$L$5001,">="&$B$4,Ventas!$L$2:$L$5001,"<="&$B$5,Ventas!$H$2:$H$5001,$B$6,Ventas!$C$2:$C$5001,Q28) -> 372000
N29: =IF(Listas!D7="","",Listas!D7) | O29: =SUMIFS(Cobros!$F$2:$F$5001,Cobros!$J$2:$J$5001,$B$3,Cobros!$K$2:$K$5001,">="&$B$4,Cobros!$K$2:$K$5001,"<="&$B$5,Cobros!$H$2:$H$5001,N29)+SUMIFS(Ventas!$I$2:$I$5001,Ventas!$K$2:$K$5001,$B$3,Ventas!$L$2:$L$5001,">="&$B$4,Ventas!$L$2:$L$5001,"<="&$B$5,Ventas!$H$2:$H$5001,N29) -> 0 | Q29: =IF(Listas!F6="","",Listas!F6) -> Dulces | R29: =SUMIFS(Ventas!$I$2:$I$5001,Ventas!$K$2:$K$5001,$B$3,Ventas!$L$2:$L$5001,">="&$B$4,Ventas!$L$2:$L$5001,"<="&$B$5,Ventas!$H$2:$H$5001,$B$6,Ventas!$C$2:$C$5001,Q29) -> 270000
N30: =IF(Listas!D8="","",Listas!D8) | O30: =SUMIFS(Cobros!$F$2:$F$5001,Cobros!$J$2:$J$5001,$B$3,Cobros!$K$2:$K$5001,">="&$B$4,Cobros!$K$2:$K$5001,"<="&$B$5,Cobros!$H$2:$H$5001,N30)+SUMIFS(Ventas!$I$2:$I$5001,Ventas!$K$2:$K$5001,$B$3,Ventas!$L$2:$L$5001,">="&$B$4,Ventas!$L$2:$L$5001,"<="&$B$5,Ventas!$H$2:$H$5001,N30) -> 0 | Q30: =IF(Listas!F7="","",Listas!F7) -> Energizantes | R30: =SUMIFS(Ventas!$I$2:$I$5001,Ventas!$K$2:$K$5001,$B$3,Ventas!$L$2:$L$5001,">="&$B$4,Ventas!$L$2:$L$5001,"<="&$B$5,Ventas!$H$2:$H$5001,$B$6,Ventas!$C$2:$C$5001,Q30) -> 742000
N31: =IF(Listas!D9="","",Listas!D9) | O31: =SUMIFS(Cobros!$F$2:$F$5001,Cobros!$J$2:$J$5001,$B$3,Cobros!$K$2:$K$5001,">="&$B$4,Cobros!$K$2:$K$5001,"<="&$B$5,Cobros!$H$2:$H$5001,N31)+SUMIFS(Ventas!$I$2:$I$5001,Ventas!$K$2:$K$5001,$B$3,Ventas!$L$2:$L$5001,">="&$B$4,Ventas!$L$2:$L$5001,"<="&$B$5,Ventas!$H$2:$H$5001,N31) -> 0 | Q31: =IF(Listas!F8="","",Listas!F8) -> Galletas | R31: =SUMIFS(Ventas!$I$2:$I$5001,Ventas!$K$2:$K$5001,$B$3,Ventas!$L$2:$L$5001,">="&$B$4,Ventas!$L$2:$L$5001,"<="&$B$5,Ventas!$H$2:$H$5001,$B$6,Ventas!$C$2:$C$5001,Q31) -> 144000
N32: =IF(Listas!D10="","",Listas!D10) | O32: =SUMIFS(Cobros!$F$2:$F$5001,Cobros!$J$2:$J$5001,$B$3,Cobros!$K$2:$K$5001,">="&$B$4,Cobros!$K$2:$K$5001,"<="&$B$5,Cobros!$H$2:$H$5001,N32)+SUMIFS(Ventas!$I$2:$I$5001,Ventas!$K$2:$K$5001,$B$3,Ventas!$L$2:$L$5001,">="&$B$4,Ventas!$L$2:$L$5001,"<="&$B$5,Ventas!$H$2:$H$5001,N32) -> 0 | Q32: =IF(Listas!F9="","",Listas!F9) -> Gaseosas | R32: =SUMIFS(Ventas!$I$2:$I$5001,Ventas!$K$2:$K$5001,$B$3,Ventas!$L$2:$L$5001,">="&$B$4,Ventas!$L$2:$L$5001,"<="&$B$5,Ventas!$H$2:$H$5001,$B$6,Ventas!$C$2:$C$5001,Q32) -> 414000
N33: =IF(Listas!D11="","",Listas!D11) | O33: =SUMIFS(Cobros!$F$2:$F$5001,Cobros!$J$2:$J$5001,$B$3,Cobros!$K$2:$K$5001,">="&$B$4,Cobros!$K$2:$K$5001,"<="&$B$5,Cobros!$H$2:$H$5001,N33)+SUMIFS(Ventas!$I$2:$I$5001,Ventas!$K$2:$K$5001,$B$3,Ventas!$L$2:$L$5001,">="&$B$4,Ventas!$L$2:$L$5001,"<="&$B$5,Ventas!$H$2:$H$5001,N33) -> 0 | Q33: =IF(Listas!F10="","",Listas!F10) -> Snacks | R33: =SUMIFS(Ventas!$I$2:$I$5001,Ventas!$K$2:$K$5001,$B$3,Ventas!$L$2:$L$5001,">="&$B$4,Ventas!$L$2:$L$5001,"<="&$B$5,Ventas!$H$2:$H$5001,$B$6,Ventas!$C$2:$C$5001,Q33) -> 235000
N34: =IF(Listas!D12="","",Listas!D12) | O34: =SUMIFS(Cobros!$F$2:$F$5001,Cobros!$J$2:$J$5001,$B$3,Cobros!$K$2:$K$5001,">="&$B$4,Cobros!$K$2:$K$5001,"<="&$B$5,Cobros!$H$2:$H$5001,N34)+SUMIFS(Ventas!$I$2:$I$5001,Ventas!$K$2:$K$5001,$B$3,Ventas!$L$2:$L$5001,">="&$B$4,Ventas!$L$2:$L$5001,"<="&$B$5,Ventas!$H$2:$H$5001,N34) -> 0 | Q34: =IF(Listas!F11="","",Listas!F11) | R34: =SUMIFS(Ventas!$I$2:$I$5001,Ventas!$K$2:$K$5001,$B$3,Ventas!$L$2:$L$5001,">="&$B$4,Ventas!$L$2:$L$5001,"<="&$B$5,Ventas!$H$2:$H$5001,$B$6,Ventas!$C$2:$C$5001,Q34) -> 0
Q35: =IF(Listas!F12="","",Listas!F12) | R35: =SUMIFS(Ventas!$I$2:$I$5001,Ventas!$K$2:$K$5001,$B$3,Ventas!$L$2:$L$5001,">="&$B$4,Ventas!$L$2:$L$5001,"<="&$B$5,Ventas!$H$2:$H$5001,$B$6,Ventas!$C$2:$C$5001,Q35) -> 0
Q36: =IF(Listas!F13="","",Listas!F13) | R36: =SUMIFS(Ventas!$I$2:$I$5001,Ventas!$K$2:$K$5001,$B$3,Ventas!$L$2:$L$5001,">="&$B$4,Ventas!$L$2:$L$5001,"<="&$B$5,Ventas!$H$2:$H$5001,$B$6,Ventas!$C$2:$C$5001,Q36) -> 0
T40: Llegadas por hora
T41: Nombre | U41: Valor
T42: 5 | U42: =COUNTIFS(Cobros!$J$2:$J$5001,$B$3,Cobros!$K$2:$K$5001,">="&$B$4,Cobros!$K$2:$K$5001,"<="&$B$5,Cobros!$H$2:$H$5001,$B$6,Cobros!$L$2:$L$5001,VALUE(T42)) -> 0
T43: 6 | U43: =COUNTIFS(Cobros!$J$2:$J$5001,$B$3,Cobros!$K$2:$K$5001,">="&$B$4,Cobros!$K$2:$K$5001,"<="&$B$5,Cobros!$H$2:$H$5001,$B$6,Cobros!$L$2:$L$5001,VALUE(T43)) -> 70
T44: 7 | U44: =COUNTIFS(Cobros!$J$2:$J$5001,$B$3,Cobros!$K$2:$K$5001,">="&$B$4,Cobros!$K$2:$K$5001,"<="&$B$5,Cobros!$H$2:$H$5001,$B$6,Cobros!$L$2:$L$5001,VALUE(T44)) -> 139
T45: 8 | U45: =COUNTIFS(Cobros!$J$2:$J$5001,$B$3,Cobros!$K$2:$K$5001,">="&$B$4,Cobros!$K$2:$K$5001,"<="&$B$5,Cobros!$H$2:$H$5001,$B$6,Cobros!$L$2:$L$5001,VALUE(T45)) -> 132
...

Sheet Listas
A1: Meses | B1: N° | C1: Mes filtro | D1: Trabajador filtro | E1: Años | F1: Categorías de la tienda
A2: Ene | B2: 1 | C2: Todos | D2: Todos | E2: 2024 | F2: Agua
A3: Feb | B3: 2 | C3: Ene | D3: Andrea Bolívar | E3: 2025 | F3: Bebidas
A4: Mar | B4: 3 | C4: Feb | D4: Carlos Perdomo | E4: 2026 | F4: Café
A5: Abr | B5: 4 | C5: Mar | D5: Luisa Trujillo | E5: 2027 | F5: Cerveza
A6: May | B6: 5 | C6: Abr | E6: 2028 | F6: Dulces
A7: Jun | B7: 6 | C7: May | F7: Energizantes
A8: Jul | B8: 7 | C8: Jun | F8: Galletas
A9: Ago | B9: 8 | C9: Jul | F9: Gaseosas
A10: Sep | B10: 9 | C10: Ago | F10: Snacks
A11: Oct | B11: 10 | C11: Sep
A12: Nov | B12: 11 | C12: Oct
A13: Dic | B13: 12 | C13: Nov
C14: Dic | D14: ← Escriba aquí sus trabajadores (hasta 10, desde D3). | F14: ← Escriba aquí sus categorías (hasta 12, desde F2).
